<?xml version="1.0"?>
<robot name="hopper">
  <material name="yellow">
    <color rgba=".8 .6 .4 1"/>
  </material>
  <material name="red">
    <color rgba=".9 .1 0 1"/>
  </material>
  <material name="blue">
    <color rgba="0.1 0.3 0.5 1"/>
  </material>

  <!-- Torso -->
  <link name="torso">
    <inertial>
      <origin xyz="0 0 0" rpy="0 1.570796326790 0"/>
      <mass value="1"/>
      <inertia ixx="0.013" ixy="0" ixz="0" iyy=".013" iyz="0" izz="0.013"/>
    </inertial>
    <visual>
      <origin xyz="0 0 0" rpy="0 1.570796326790 0"/>
      <geometry>
        <capsule length="0.4" radius=".05"/>
      </geometry>
      <material name="yellow"/>
    </visual>
    <!--
    <collision>
      <origin xyz="0 0 0" rpy="0 1.570796326790 0"/>
      <geometry>
        <capsule length="0.4" radius=".05"/>
      </geometry>
    </collision>
    -->
  </link>
  <joint name="base_joint" type="planar">
    <parent link="world"/>
    <child link="torso"/>
    <axis xyz="0 -1 0"/>
    <origin xyz="0 0 0" rpy="0 -1.570796326790 0"/>
  </joint>

  <!-- Leg --> 
  <link name="leg">
    <inertial>
      <origin xyz="-0.2 0 0" rpy="0 1.570796326790 0"/>
      <mass value="0.2"/>
      <inertia ixx="0.01" ixy="0" ixz="0" iyy="0.01" iyz="0" izz="0.01"/>
    </inertial>
    <visual>
      <origin xyz="-0.2 0 0" rpy="0 1.570796326790 0"/>
      <geometry>
        <capsule length="0.4" radius=".03"/>
      </geometry>
      <material name="yellow"/>
    </visual>
  </link>
  <joint name="knee" type="revolute">
    <parent link="torso"/>
    <child link="leg"/>
    <origin xyz="-0.2 0 0"/>
    <axis xyz="0 -1 0"/>
  </joint>
  
  <!-- Foot --> 
  <link name="foot">
    <inertial>
      <origin xyz="0 0 -0.05" rpy="0 0 0"/>
      <mass value="0.1"/>
      <inertia ixx="0.005" ixy="0" ixz="0" iyy="0.005" iyz="0" izz="0.005"/>
    </inertial>
    <visual>
      <origin xyz="0 0 -0.05" rpy="0 0 0"/>
      <geometry>
        <capsule length="0.2" radius=".03"/>
      </geometry>
      <material name="yellow"/>
    </visual>
    <collision>
      <origin xyz="0 0 -0.15" rpy="0 0 0"/>
      <geometry>
        <sphere radius=".03"/>
      </geometry>
    </collision>
    <collision>
      <origin xyz="0 0 0.05" rpy="0 0 0"/>
      <geometry>
        <sphere radius=".03"/>
      </geometry>
    </collision>
  </link>
  <joint name="ankle" type="revolute">
    <parent link="leg"/>
    <child link="foot"/>
    <origin xyz="-0.4 0 0"/>
    <axis xyz="0 -1 0"/>
  </joint>

  <!-- Actuators --> 
  <transmission type="SimpleTransmission" name="knee_trans">
    <actuator name="knee"/>
    <joint name="knee"/>
    <mechanicalReduction>1</mechanicalReduction>
  </transmission>
  <transmission type="SimpleTransmission" name="ankle_trans">
    <actuator name="ankle"/>
    <joint name="ankle"/>
    <mechanicalReduction>1</mechanicalReduction>
  </transmission>

</robot>
