<?xml version="1.0" ?>
<robot name="mini_cheetah" xmlns:xacro="http://ros.org/wiki/xacro">
    <!--!!!!!!!!!!!!!!!!!! Ground !!!!!!!!!!!!!!!!!!!!!!!!!!!!!-->
    <link name="ground">
        <inertial>
            <inertia ixx="0" ixy="0" ixz="0" iyy="0" iyz="0" izz="0"/>
            <mass value="0"/>
            <origin rpy="0 0 0" xyz="0 0 -5"/>
        </inertial>
        <collision>
            <geometry>
                <box size="10 10 10"/>
            </geometry>
            <origin rpy="0 0 0" xyz="0 0 -5"/>
        </collision>
    </link>
    <joint name="world_to_ground" type="fixed">
        <parent link="world"/>
        <child link="ground"/>
        <origin rpy="0 0 0" xyz="0 0 0"/>
    </joint>

    <!--!!!!!!!!!!!!!!!!!! Body !!!!!!!!!!!!!!!!!!!!!!!!!!!!!!!-->
    <link name="body">
        <inertial>
            <mass value="3.3"/>
            <origin rpy="0 0 0" xyz="0 0 0"/>
            <inertia ixx="0.012677" ixy="0" ixz="0" iyy="0.017298" iyz="0" izz="0.024475"/>
        </inertial>
        <visual>
            <geometry>
                <mesh filename="meshes/mini_body.obj"/>
            </geometry>
            <origin rpy="0.0 0.0 0.0" xyz="0.0 0.0 0.0"/>
        </visual>
        <collision>
            <geometry>
                <box size="0.23 0.19 0.1"/>
            </geometry>
            <!--
            <drake:proximity_properties>
                <drake:compliant_hydroelastic/>
                <drake:mesh_resolution_hint value="0.05"/>
                <drake:hydroelastic_modulus value="1e4"/>
                <drake:hunt_crossley_dissipation value="1.25"/>
            </drake:proximity_properties>
            -->
            <origin rpy="0 0 0" xyz="0 0 0"/>
        </collision>
    </link>

    <!--!!!!!!!!!!!! Front Left Leg !!!!!!!!!!!!!!!!!!!!!!!!!!!!!!!!!!!!-->
    <joint name="torso_to_abduct_fl_j" type="continuous">
        <axis xyz="1 0 0"/>
        <origin rpy="0 0 0" xyz="0.19 0.049 0.0"/>
        <parent link="body"/>
        <child link="abduct_fl"/>
        <limit effort="18" lower="-1.6" upper="1.6" velocity="40"/>
    </joint>
    <link name="abduct_fl">
        <inertial>
            <mass value="0.54"/>
            <origin rpy="0 0 0" xyz="-0.020141 0.0031565 -0.00030165"/>
            <inertia ixx="0.00024813" ixy="-7.3073e-05" ixz="-8.4353e-08" iyy="0.00054315" iyz="-3.811e-07" izz="0.00045809"/>
        </inertial>
        <visual>
            <geometry>
                <mesh filename="meshes/mini_abad.obj"/>
            </geometry>
            <origin rpy="0. 0. -1.5708" xyz="-0.055 0.0 0.0"/>
        </visual>
        <!--
        <collision>
            <geometry>
                <cylinder length ="0.02" radius = "0.0475"/>
            </geometry>
            <drake:proximity_properties>
                <drake:compliant_hydroelastic/>
                <drake:mesh_resolution_hint value="0.05"/>
                <drake:hydroelastic_modulus value="1e5"/>
                <drake:hunt_crossley_dissipation value="1.25"/>
            </drake:proximity_properties>
            <origin rpy="0 1.5708 -1.5708" xyz="-0.055 0.0 0.0"/>
        </collision>
        <collision>
            <geometry>
                <cylinder length ="0.06" radius = "0.0475"/>
            </geometry>
            <drake:proximity_properties>
                <drake:compliant_hydroelastic/>
                <drake:mesh_resolution_hint value="0.05"/>
                <drake:hydroelastic_modulus value="1e5"/>
                <drake:hunt_crossley_dissipation value="1.25"/>
            </drake:proximity_properties>
            <origin rpy="1.5708 0.0 0.0" xyz="0.0 0.0 0.0"/>
        </collision>-->
    </link>

    <joint name="abduct_fl_to_thigh_fl_j" type="continuous">
        <axis xyz="0 -1 0"/>
        <origin rpy="0.0 0.0 0.0" xyz="0.0 0.062 0.00"/>
        <parent link="abduct_fl"/>
        <child link="thigh_fl"/>
        <limit effort="18" lower="-2.6" upper="2.6" velocity="40"/>
    </joint>
    <link name="thigh_fl">
        <inertial>
            <mass value="0.634"/>
            <origin rpy="0 0 0" xyz="4.6618e-05 0.00010106 -0.015538"/>
            <inertia ixx="0.0019421" ixy="-1.9868e-08" ixz="4.2744e-09" iyy="0.0017224" iyz="8.4495e-05" izz="0.00066017"/>
        </inertial>
        <visual>
            <geometry>
                <mesh filename="meshes/mini_upper_link.obj"/>
            </geometry>
            <origin rpy="0.0 -1.5708 3.1415" xyz="0.0 0.0 0.0"/>
        </visual>
        <!--
        <collision>
            <geometry>
                <cylinder length ="0.21" radius = "0.025"/>
            </geometry>
            <drake:proximity_properties>
                <drake:compliant_hydroelastic/>
                <drake:mesh_resolution_hint value="0.05"/>
                <drake:hydroelastic_modulus value="1e3"/>
                <drake:hunt_crossley_dissipation value="1.25"/>
            </drake:proximity_properties>
            <origin rpy="0.0 0.0 0.0" xyz="0.0 0.0 -0.105"/>
        </collision>-->
    </link>

    <joint name="thigh_fl_to_knee_fl_j" type="continuous">
        <axis xyz="0 -1 0"/>
        <origin rpy="0.0 0 0.0" xyz="0.0 0.0 -0.209"/>
        <parent link="thigh_fl"/>
        <child link="shank_fl"/>
        <limit effort="26" lower="-2.6" upper="2.6" velocity="26"/>
    </joint>
    <link name="shank_fl">
        <inertial>
            <mass value="0.064"/>
            <origin rpy="0 0 0" xyz="0.00019682 0.00087559 -0.089454"/>
            <inertia ixx="0.00034489" ixy="-1.7324e-09" ixz="-4.1535e-07" iyy="0.00034717" iyz="-1.1541e-06" izz="5.7021e-06"/>
        </inertial>
        <visual>
            <geometry>
                <mesh filename="meshes/mini_lower_link.obj"/>
            </geometry>
            <origin rpy="0.0 3.141592 0.0" xyz="0.0 0.0 0.0"/>
        </visual>
        <!--
        <collision>
            <geometry>
                <cylinder length ="0.19" radius = "0.015"/>
            </geometry>
            <origin rpy="0.0 3.141592 0.0" xyz="0 0 -0.095"/>
        </collision>
        <collision>
            <geometry>
                <sphere radius = "0.0175"/>
            </geometry>
            <origin rpy="0.0 3.141592 0.0" xyz="0 0 -0.195"/>
        </collision>
        -->
    </link>


    <!--!!!!!!!!!!!! Front Right Leg !!!!!!!!!!!!!!!!!!!!!!!!!!!!!!!!!!!!-->
    <joint name="torso_to_abduct_fr_j" type="continuous">
        <axis xyz="1 0 0"/>
        <origin rpy="0 0 0" xyz="0.19 -0.049 0.0"/>
        <parent link="body"/>
        <child link="abduct_fr"/>
        <limit effort="18" lower="-1.6" upper="1.6" velocity="40"/>
    </joint>
    <link name="abduct_fr">
        <inertial>
            <mass value="0.54"/>
            <origin rpy="0 0 0" xyz="-0.020141 -0.0031565 0.00030167"/>
            <inertia ixx="0.00024813" ixy="7.3073e-05" ixz="8.4215e-08" iyy="0.00054315" iyz="-3.8105e-07" izz="0.00045809"/>
        </inertial>
        <visual>
            <geometry>
                <mesh filename="meshes/mini_abad.obj"/>
            </geometry>
            <origin rpy="3.141592 0.0 1.5708" xyz="-0.055 0.0 0.0"/>
        </visual>
        <!--
        <collision>
            <geometry>
                <cylinder length ="0.02" radius = "0.0475"/>
            </geometry>
            <origin rpy="3.141592 1.5708 1.5708" xyz="-0.055 0 0"/>
        </collision>
        <collision>
            <geometry>
                <cylinder length ="0.06" radius = "0.0475"/>
            </geometry>
            <origin rpy="1.5708 0.0 0.0" xyz="-0.055 0 0"/>
        </collision>
        -->
    </link>

    <joint name="abduct_fr_to_thigh_fr_j" type="continuous">
        <axis xyz="0 -1 0"/>
        <origin rpy="0.0 0.0 0.0" xyz="0.0 -0.062 0.00"/>
        <parent link="abduct_fr"/>
        <child link="thigh_fr"/>
        <limit effort="18" lower="-2.6" upper="2.6" velocity="40"/>
    </joint>
    <link name="thigh_fr">
        <inertial>
            <mass value="0.634"/>
            <origin rpy="0 0 0" xyz="-4.6609e-05 -0.00010107 -0.015538"/>
            <inertia ixx="0.0019421" ixy="4.8747e-10" ixz="3.5543e-09" iyy="0.0017224" iyz="-8.4495e-05" izz="0.00066017"/>
        </inertial>
        <visual>
            <geometry>
                <mesh filename="meshes/mini_upper_link.obj"/>
            </geometry>
            <origin rpy="0.0 -1.5708 0.0" xyz="0.0 0.0 0.0"/>
        </visual>
        <!--
        <collision>
            <geometry>
                <cylinder length ="0.21" radius = "0.025"/>
            </geometry>
            <drake:proximity_properties>
                <drake:compliant_hydroelastic/>
                <drake:mesh_resolution_hint value="0.05"/>
                <drake:hydroelastic_modulus value="1e4"/>
                <drake:hunt_crossley_dissipation value="1.25"/>
            </drake:proximity_properties>
            <origin rpy="0.0 0.0 0.0" xyz="0.0 0.0 -0.105"/>
        </collision>-->
    </link>

    <joint name="thigh_fr_to_knee_fr_j" type="continuous">
        <axis xyz="0 -1 0"/>
        <origin rpy="0.0 0 0.0" xyz="0.0 0.0 -0.209"/>
        <parent link="thigh_fr"/>
        <child link="shank_fr"/>
        <limit effort="26" lower="-2.6" upper="2.6" velocity="26"/>
    </joint>
    <link name="shank_fr">
        <inertial>
            <mass value="0.064"/>
            <origin rpy="0 0 0" xyz="0.00019682 0.00087559 -0.089454"/>
            <inertia ixx="0.00034489" ixy="-1.7324e-09" ixz="-4.1535e-07" iyy="0.00034717" iyz="-1.1541e-06" izz="5.7021e-06"/>
        </inertial>
        <visual>
            <geometry>
                <mesh filename="meshes/mini_lower_link.obj"/>
            </geometry>
            <origin rpy="0.0 3.141592 0.0" xyz="0.0 0.0 0.0"/>
        </visual>
        <!--
        <collision>
            <geometry>
                <cylinder length ="0.19" radius = "0.015"/>
            </geometry>
            <origin rpy="0.0 3.141592 0.0" xyz="0.0 0.0 -0.095"/>
        </collision>
        <collision>
            <geometry>
                <sphere radius = "0.0175"/>
            </geometry>
            <origin rpy="0.0 3.141592 0" xyz="0.0 0.0 -0.195"/>
        </collision>
        -->
    </link>


    <!--!!!!!!!!!!!! Hind Left Leg !!!!!!!!!!!!!!!!!!!!!!!!!!!!!!!!!!!!-->
    <joint name="torso_to_abduct_hl_j" type="continuous">
        <axis xyz="1 0 0"/>
        <origin rpy="0 0 0" xyz="-0.19 0.049 0.0"/>
        <parent link="body"/>
        <child link="abduct_hl"/>
        <limit effort="18" lower="-1.6" upper="1.6" velocity="40"/>
    </joint>
    <link name="abduct_hl">
        <inertial>
            <mass value="0.54"/>
            <origin rpy="0 0 0" xyz="0.020141 0.0031568 0.00030167"/>
            <inertia ixx="0.00024813" ixy="7.3075e-05" ixz="-8.4213e-08" iyy="0.00054315" iyz="3.8105e-07" izz="0.00045809"/>
        </inertial>
        <visual>
            <geometry>
                <mesh filename="meshes/mini_abad.obj"/>
            </geometry>
            <origin rpy="3.141592 0.0 -1.5708" xyz="0.055 0.0 0.0"/>
        </visual>
        <!--
        <collision>
            <geometry>
                <cylinder length ="0.02" radius = "0.0475"/>
            </geometry>
            <origin rpy="3.141592 1.5708 -1.5708" xyz="0.055 0 0"/>
        </collision>
        <collision>
            <geometry>
                <cylinder length ="0.06" radius = "0.0475"/>
            </geometry>
            <origin rpy="1.5708 0.0 0.0" xyz="0.0 0.0 0.0"/>
        </collision>
        -->
    </link>

    <joint name="abduct_hl_to_thigh_hl_j" type="continuous">
        <axis xyz="0 -1 0"/>
        <origin rpy="0.0 0.0 0.0" xyz="0.0 0.062 0.00"/>
        <parent link="abduct_hl"/>
        <child link="thigh_hl"/>
        <limit effort="18" lower="-2.6" upper="2.6" velocity="40"/>
    </joint>
    <link name="thigh_hl">
        <inertial>
            <mass value="0.634"/>
            <origin rpy="0 0 0" xyz="4.6618e-05 0.00010106 -0.015538"/>
            <inertia ixx="0.0019421" ixy="-1.9868e-08" ixz="4.2744e-09" iyy="0.0017224" iyz="8.4495e-05" izz="0.00066017"/>
        </inertial>
        <visual>
            <geometry>
                <mesh filename="meshes/mini_upper_link.obj"/>
            </geometry>
            <origin rpy="0.0 -1.5708 3.1415" xyz="0.0 0.0 0.0"/>
        </visual>
        <!--
        <collision>
            <geometry>
                <cylinder length ="0.21" radius = "0.025"/>
            </geometry>
            <origin rpy="0.0 0.0 0.0" xyz="0.0 0.0 -0.105"/>
            <drake:proximity_properties>
                <drake:compliant_hydroelastic/>
                <drake:mesh_resolution_hint value="0.05"/>
                <drake:hydroelastic_modulus value="1e4"/>
                <drake:hunt_crossley_dissipation value="1.25"/>
            </drake:proximity_properties>
        </collision>-->
    </link>

    <joint name="thigh_hl_to_knee_hl_j" type="continuous">
        <axis xyz="0 -1 0"/>
        <origin rpy="0.0 0 0.0" xyz="0.0 0.0 -0.209"/>
        <parent link="thigh_hl"/>
        <child link="shank_hl"/>
        <limit effort="26" lower="-2.6" upper="2.6" velocity="26"/>
    </joint>
    <link name="shank_hl">
        <inertial>
            <mass value="0.064"/>
            <origin rpy="0 0 0" xyz="0.00019682 0.00087559 -0.089454"/>
            <inertia ixx="0.00034489" ixy="-1.7324e-09" ixz="-4.1535e-07" iyy="0.00034717" iyz="-1.1541e-06" izz="5.7021e-06"/>
        </inertial>
        <visual>
            <geometry>
                <mesh filename="meshes/mini_lower_link.obj"/>
            </geometry>
            <origin rpy="0.0 3.141592 0.0" xyz="0.0 0.0 0.0"/>
        </visual>
        <!--
        <collision>
            <geometry>
                <cylinder length ="0.19" radius = "0.015"/>
            </geometry>
            <origin rpy="0.0 3.141592 0.0" xyz="0.0 0.0 -0.095"/>
        </collision>
        <collision>
            <geometry>
                <sphere radius = "0.0175"/>
            </geometry>
            <origin rpy="0.0 3.141592 0.0" xyz="0.0 0.0 -0.195"/>
        </collision>
        -->
    </link>


    <!--!!!!!!!!!!!! Hind Right Leg !!!!!!!!!!!!!!!!!!!!!!!!!!!!!!!!!!!!-->
    <joint name="torso_to_abduct_hr_j" type="continuous">
        <axis xyz="1 0 0"/>
        <origin rpy="0 0 0" xyz="-0.19 -0.049 0.0"/>
        <parent link="body"/>
        <child link="abduct_hr"/>
        <limit effort="18" lower="-1.6" upper="1.6" velocity="40"/>
    </joint>
    <link name="abduct_hr">
        <inertial>
            <mass value="0.54"/>
            <origin rpy="0 0 0" xyz="0.020141 -0.0031568 -0.00030165"/>
            <inertia ixx="0.00024813" ixy="-7.3075e-05" ixz="8.435e-08" iyy="0.00054315" iyz="3.811e-07" izz="0.00045809"/>
        </inertial>
        <visual>
            <geometry>
                <mesh filename="meshes/mini_abad.obj"/>
            </geometry>
            <origin rpy="0.0 0.0 1.5708" xyz="0.055 0.0 0.0"/>
        </visual>
        <!--
        <collision>
            <geometry>
                <cylinder length ="0.02" radius = "0.0475"/>
            </geometry>
            <origin rpy="0.0 1.5708 1.5708" xyz="0.055 0.0 0.0"/>
        </collision>
        <collision>
            <geometry>
                <cylinder length ="0.06" radius = "0.0475"/>
            </geometry>
            <origin rpy="1.5708 0.0 0.0" xyz="0.0 0.0 0.0"/>
        </collision>
        -->
    </link>

    <joint name="abduct_hr_to_thigh_hr_j" type="continuous">
        <axis xyz="0 -1 0"/>
        <origin rpy="0.0 0.0 0.0" xyz="0.0 -0.062 0.00"/>
        <parent link="abduct_hr"/>
        <child link="thigh_hr"/>
        <limit effort="18" lower="-2.6" upper="2.6" velocity="40"/>
    </joint>
    <link name="thigh_hr">
        <inertial>
            <mass value="0.634"/>
            <origin rpy="0 0 0" xyz="-4.6609e-05 -0.00010107 -0.015538"/>
            <inertia ixx="0.0019421" ixy="4.8747e-10" ixz="3.5543e-09" iyy="0.0017224" iyz="-8.4495e-05" izz="0.00066017"/>
        </inertial>
        <visual>
            <geometry>
                <mesh filename="meshes/mini_upper_link.obj"/>
            </geometry>
            <origin rpy="0.0 -1.5708 0.0" xyz="0.0 0.0 0.0"/>
        </visual>
        <!--
        <collision>
            <geometry>
                <cylinder length ="0.21" radius = "0.025"/>
            </geometry>
            <origin rpy="0.0 0.0 0.0" xyz="0.0 0.0 -0.105"/>
            <drake:proximity_properties>
                <drake:compliant_hydroelastic/>
                <drake:mesh_resolution_hint value="0.05"/>
                <drake:hydroelastic_modulus value="1e4"/>
                <drake:hunt_crossley_dissipation value="1.25"/>
            </drake:proximity_properties>
        </collision>-->
    </link>

    <joint name="thigh_hr_to_knee_hr_j" type="continuous">
        <axis xyz="0 -1 0"/>
        <origin rpy="0.0 0 0.0" xyz="0.0 0.0 -0.209"/>
        <parent link="thigh_hr"/>
        <child link="shank_hr"/>
        <limit effort="26" lower="-2.6" upper="2.6" velocity="26"/>
    </joint>
    <link name="shank_hr">
        <inertial>
            <mass value="0.064"/>
            <origin rpy="0 0 0" xyz="0.00019682 0.00087559 -0.089454"/>
            <inertia ixx="0.00034489" ixy="-1.7324e-09" ixz="-4.1535e-07" iyy="0.00034717" iyz="-1.1541e-06" izz="5.7021e-06"/>
        </inertial>
        <visual>
            <geometry>
                <mesh filename="meshes/mini_lower_link.obj"/>
            </geometry>
            <origin rpy="0.0 3.141592 0.0" xyz="0 0 0"/>
        </visual>
        <!--
        <collision>
            <geometry>
                <cylinder length ="0.19" radius = "0.015"/>
            </geometry>
            <origin rpy="0.0 3.141592 0.0" xyz="0 0 -0.095"/>
        </collision>
        <collision>
            <geometry>
                <sphere radius = "0.0175"/>
            </geometry>
            <origin rpy="0.0 3.141592 0.0" xyz="0.0 0.0 -0.195"/>
        </collision>
        -->
    </link>

    <!-- Add foot links to enable relevent computations, including better collision detection -->
    <joint name="shank_fl_to_foot_fl" type="fixed">
        <parent link="shank_fl"/>
        <child link="LF_FOOT"/>
        <origin rpy="0.0 0.0 0.0" xyz="0.0 0.0 -0.190"/>
    </joint>
    <link name="LF_FOOT">
        <inertial>
            <inertia ixx="0" ixy="0" ixz="0" iyy="0" iyz="0" izz="0"/>
            <mass value="0"/>
            <origin rpy="0 0 0" xyz="0 0 0"/>
        </inertial>
        <collision>
            <geometry>
                <sphere radius = "0.0175"/>
            </geometry>
            <!--
            <drake:proximity_properties>
                <drake:rigid_hydroelastic/>
                <drake:mesh_resolution_hint value="0.02"/>
                <drake:hydroelastic_modulus value="5e6"/>
                <drake:hunt_crossley_dissipation value="1.25"/>
            </drake:proximity_properties>-->
            <origin rpy="0.0 0.0 0.0" xyz="0.0 0.0 0.0"/>
        </collision>
        <visual>
            <geometry>
                <sphere radius = "0.0175"/>
            </geometry>
            <origin rpy="0.0 0.0 0.0" xyz="0.0 0.0 0.0"/>
        </visual>
    </link>
    
    <joint name="shank_fr_to_foot_fr" type="fixed">
        <parent link="shank_fr"/>
        <child link="RF_FOOT"/>
        <origin rpy="0.0 0.0 0.0" xyz="0.0 0.0 -0.190"/>
    </joint>
    <link name="RF_FOOT">
        <inertial>
            <inertia ixx="0" ixy="0" ixz="0" iyy="0" iyz="0" izz="0"/>
            <mass value="0"/>
            <origin rpy="0 0 0" xyz="0 0 0"/>
        </inertial>
        <collision>
            <geometry>
                <sphere radius = "0.0175"/>
            </geometry>
            <!--
            <drake:proximity_properties>
                <drake:rigid_hydroelastic/>
                <drake:mesh_resolution_hint value="0.02"/>
                <drake:hydroelastic_modulus value="5e6"/>
                <drake:hunt_crossley_dissipation value="1.25"/>
            </drake:proximity_properties>
            -->
            <origin rpy="0.0 0.0 0.0" xyz="0.0 0.0 0.0"/>
        </collision>
        <visual>
            <geometry>
                <sphere radius = "0.0175"/>
            </geometry>
            <origin rpy="0.0 0.0 0.0" xyz="0.0 0.0 0.0"/>
        </visual>
    </link>
    
    <joint name="shank_hl_to_foot_hl" type="fixed">
        <parent link="shank_hl"/>
        <child link="LH_FOOT"/>
        <origin rpy="0.0 0.0 0.0" xyz="0.0 0.0 -0.190"/>
    </joint>
    <link name="LH_FOOT">
        <inertial>
            <inertia ixx="0" ixy="0" ixz="0" iyy="0" iyz="0" izz="0"/>
            <mass value="0"/>
            <origin rpy="0 0 0" xyz="0 0 0"/>
        </inertial>
        <collision>
            <geometry>
                <sphere radius = "0.0175"/>
            </geometry>
            <!--
            <drake:proximity_properties>
                <drake:rigid_hydroelastic/>
                <drake:mesh_resolution_hint value="0.02"/>
                <drake:hydroelastic_modulus value="5e6"/>
                <drake:hunt_crossley_dissipation value="1.25"/>
            </drake:proximity_properties>
            -->
            <origin rpy="0.0 0.0 0.0" xyz="0.0 0.0 0.0"/>
        </collision>
        <visual>
            <geometry>
                <sphere radius = "0.0175"/>
            </geometry>
            <origin rpy="0.0 0.0 0.0" xyz="0.0 0.0 0.0"/>
        </visual>
    </link>
    
    <joint name="shank_hr_to_foot_hr" type="fixed">
        <parent link="shank_hr"/>
        <child link="RH_FOOT"/>
        <origin rpy="0.0 0.0 0.0" xyz="0.0 0.0 -0.190"/>
    </joint>
    <link name="RH_FOOT">
        <inertial>
            <inertia ixx="0" ixy="0" ixz="0" iyy="0" iyz="0" izz="0"/>
            <mass value="0"/>
            <origin rpy="0 0 0" xyz="0 0 0"/>
        </inertial>
        <collision>
            <geometry>
                <sphere radius = "0.0175"/>
            </geometry>
            <!--
            <drake:proximity_properties>
                <drake:rigid_hydroelastic/>
                <drake:mesh_resolution_hint value="0.02"/>
                <drake:hydroelastic_modulus value="5e6"/>
                <drake:hunt_crossley_dissipation value="1.25"/>
            </drake:proximity_properties>
            -->
            <origin rpy="0.0 0.0 0.0" xyz="0.0 0.0 0.0"/>
        </collision>
        <visual>
            <geometry>
                <sphere radius = "0.0175"/>
            </geometry>
            <origin rpy="0.0 0.0 0.0" xyz="0.0 0.0 0.0"/>
        </visual>
    </link>

    <!-- Joint Transmissions: Tells Drake that these are actuated -->
    <transmission name="torso_to_abduct_fl_j_transmission">
        <type>transmission_interface/SimpleTransmission</type>
        <joint name="torso_to_abduct_fl_j"/>
        <actuator name="torso_to_abduct_fl_j_actuator"/>
    </transmission>
    <transmission name="abduct_fl_to_thigh_fl_j_transmission">
        <type>transmission_interface/SimpleTransmission</type>
        <joint name="abduct_fl_to_thigh_fl_j"/>
        <actuator name="abduct_fl_to_thigh_fl_j_actuator"/>
    </transmission>
    <transmission name="thigh_fl_to_knee_fl_j_transmission">
        <type>transmission_interface/SimpleTransmission</type>
        <joint name="thigh_fl_to_knee_fl_j"/>
        <actuator name="thigh_fl_to_knee_fl_j_actuator"/>
    </transmission>

    <transmission name="torso_to_abduct_fr_j_transmission">
        <type>transmission_interface/SimpleTransmission</type>
        <joint name="torso_to_abduct_fr_j"/>
        <actuator name="torso_to_abduct_fr_j_actuator"/>
    </transmission>
    <transmission name="abduct_fr_to_thigh_fr_j_transmission">
        <type>transmission_interface/SimpleTransmission</type>
        <joint name="abduct_fr_to_thigh_fr_j"/>
        <actuator name="abduct_fr_to_thigh_fr_j_actuator"/>
    </transmission>
    <transmission name="thigh_fr_to_knee_fr_j_transmission">
        <type>transmission_interface/SimpleTransmission</type>
        <joint name="thigh_fr_to_knee_fr_j"/>
        <actuator name="thigh_fr_to_knee_fr_j_actuator"/>
    </transmission>

    <transmission name="torso_to_abduct_hl_j_transmission">
        <type>transmission_interface/SimpleTransmission</type>
        <joint name="torso_to_abduct_hl_j"/>
        <actuator name="torso_to_abduct_hl_j_actuator"/>
    </transmission>
    <transmission name="abduct_hl_to_thigh_hl_j_transmission">
        <type>transmission_interface/SimpleTransmission</type>
        <joint name="abduct_hl_to_thigh_hl_j"/>
        <actuator name="abduct_hl_to_thigh_hl_j_actuator"/>
    </transmission>
    <transmission name="thigh_hl_to_knee_hl_j_transmission">
        <type>transmission_interface/SimpleTransmission</type>
        <joint name="thigh_hl_to_knee_hl_j"/>
        <actuator name="thigh_hl_to_knee_hl_j_actuator"/>
    </transmission>

    <transmission name="torso_to_abduct_hr_j_transmission">
        <type>transmission_interface/SimpleTransmission</type>
        <joint name="torso_to_abduct_hr_j"/>
        <actuator name="torso_to_abduct_hr_j_actuator"/>
    </transmission>
    <transmission name="abduct_hr_to_thigh_hr_j_transmission">
        <type>transmission_interface/SimpleTransmission</type>
        <joint name="abduct_hr_to_thigh_hr_j"/>
        <actuator name="abduct_hr_to_thigh_hr_j_actuator"/>
    </transmission>
    <transmission name="thigh_hr_to_knee_hr_j_transmission">
        <type>transmission_interface/SimpleTransmission</type>
        <joint name="thigh_hr_to_knee_hr_j"/>
        <actuator name="thigh_hr_to_knee_hr_j_actuator"/>
    </transmission>
    <!-- Ingore self-collisions for now -->
    <drake:collision_filter_group name="feet">
        <drake:member link="LF_FOOT"/>
        <drake:member link="RF_FOOT"/>
        <drake:member link="LH_FOOT"/>
        <drake:member link="RH_FOOT"/>
        <drake:ignored_collision_filter_group name="feet"/>
    </drake:collision_filter_group>
</robot>
